ðŸš€ Training ResNet18 from Scratch (224Ã—224)...
âœ… Resized dataset (on-the-fly): 50000 train samples, 10000 test samples
--- Logging error ---
Traceback (most recent call last):
  File "c:\Users\SHARS\AppData\Local\Programs\Python\Python311\Lib\logging\__init__.py", line 1113, in emit
    stream.write(msg + self.terminator)
  File "c:\Users\SHARS\AppData\Local\Programs\Python\Python311\Lib\encodings\cp1252.py", line 19, in encode
    return codecs.charmap_encode(input,self.errors,encoding_table)[0]
           ^^^^^^^^^^^^^^^^^^^^^^^^^^^^^^^^^^^^^^^^^^^^^^^^^^^^^^^
UnicodeEncodeError: 'charmap' codec can't encode characters in position 139-140: character maps to <undefined>
Call stack:
  File "<frozen runpy>", line 198, in _run_module_as_main
  File "<frozen runpy>", line 88, in _run_code
  File "C:\Users\SHARS\AppData\Roaming\Python\Python311\site-packages\ipykernel_launcher.py", line 18, in <module>
    app.launch_new_instance()
  File "C:\Users\SHARS\AppData\Roaming\Python\Python311\site-packages\traitlets\config\application.py", line 1075, in launch_instance
    app.start()
  File "C:\Users\SHARS\AppData\Roaming\Python\Python311\site-packages\ipykernel\kernelapp.py", line 739, in start
    self.io_loop.start()
  File "C:\Users\SHARS\AppData\Roaming\Python\Python311\site-packages\tornado\platform\asyncio.py", line 205, in start
    self.asyncio_loop.run_forever()
  File "c:\Users\SHARS\AppData\Local\Programs\Python\Python311\Lib\asyncio\base_events.py", line 608, in run_forever
    self._run_once()
  File "c:\Users\SHARS\AppData\Local\Programs\Python\Python311\Lib\asyncio\base_events.py", line 1936, in _run_once
    handle._run()
  File "c:\Users\SHARS\AppData\Local\Programs\Python\Python311\Lib\asyncio\events.py", line 84, in _run
    self._context.run(self._callback, *self._args)
  File "C:\Users\SHARS\AppData\Roaming\Python\Python311\site-packages\ipykernel\kernelbase.py", line 545, in dispatch_queue
    await self.process_one()
  File "C:\Users\SHARS\AppData\Roaming\Python\Python311\site-packages\ipykernel\kernelbase.py", line 534, in process_one
    await dispatch(*args)
  File "C:\Users\SHARS\AppData\Roaming\Python\Python311\site-packages\ipykernel\kernelbase.py", line 437, in dispatch_shell
    await result
  File "C:\Users\SHARS\AppData\Roaming\Python\Python311\site-packages\ipykernel\ipkernel.py", line 362, in execute_request
    await super().execute_request(stream, ident, parent)
  File "C:\Users\SHARS\AppData\Roaming\Python\Python311\site-packages\ipykernel\kernelbase.py", line 778, in execute_request
    reply_content = await reply_content
  File "C:\Users\SHARS\AppData\Roaming\Python\Python311\site-packages\ipykernel\ipkernel.py", line 449, in do_execute
    res = shell.run_cell(
  File "C:\Users\SHARS\AppData\Roaming\Python\Python311\site-packages\ipykernel\zmqshell.py", line 549, in run_cell
    return super().run_cell(*args, **kwargs)
  File "C:\Users\SHARS\AppData\Roaming\Python\Python311\site-packages\IPython\core\interactiveshell.py", line 3075, in run_cell
    result = self._run_cell(
  File "C:\Users\SHARS\AppData\Roaming\Python\Python311\site-packages\IPython\core\interactiveshell.py", line 3130, in _run_cell
    result = runner(coro)
  File "C:\Users\SHARS\AppData\Roaming\Python\Python311\site-packages\IPython\core\async_helpers.py", line 128, in _pseudo_sync_runner
    coro.send(None)
  File "C:\Users\SHARS\AppData\Roaming\Python\Python311\site-packages\IPython\core\interactiveshell.py", line 3334, in run_cell_async
    has_raised = await self.run_ast_nodes(code_ast.body, cell_name,
  File "C:\Users\SHARS\AppData\Roaming\Python\Python311\site-packages\IPython\core\interactiveshell.py", line 3517, in run_ast_nodes
    if await self.run_code(code, result, async_=asy):
  File "C:\Users\SHARS\AppData\Roaming\Python\Python311\site-packages\IPython\core\interactiveshell.py", line 3577, in run_code
    exec(code_obj, self.user_global_ns, self.user_ns)
  File "C:\Users\SHARS\AppData\Local\Temp\ipykernel_1256\2587197345.py", line 12, in <module>
    wandb.init(project="ResNet18_Resized", name="ResNet18_Scratch_224")
  File "c:\Users\SHARS\AppData\Local\Programs\Python\Python311\Lib\site-packages\wandb\sdk\wandb_init.py", line 1430, in init
    wi.setup_run_log_directory(run_settings)
  File "c:\Users\SHARS\AppData\Local\Programs\Python\Python311\Lib\site-packages\wandb\sdk\wandb_init.py", line 624, in setup_run_log_directory
    self._logger.info(f"Logging user logs to {settings.log_user}")
Message: 'Logging user logs to c:\\Users\\SHARS\\OneDrive\\ë¬¸ì„œ\\GitHub\\assignment-2-HarshvardhanSingh841\\wandb\\run-20250214_181939-2cmxlf90\\logs\\debug.log'
Arguments: ()
--- Logging error ---
Traceback (most recent call last):
  File "c:\Users\SHARS\AppData\Local\Programs\Python\Python311\Lib\logging\__init__.py", line 1113, in emit
    stream.write(msg + self.terminator)
  File "c:\Users\SHARS\AppData\Local\Programs\Python\Python311\Lib\encodings\cp1252.py", line 19, in encode
    return codecs.charmap_encode(input,self.errors,encoding_table)[0]
           ^^^^^^^^^^^^^^^^^^^^^^^^^^^^^^^^^^^^^^^^^^^^^^^^^^^^^^^
UnicodeEncodeError: 'charmap' codec can't encode characters in position 139-140: character maps to <undefined>
Call stack:
  File "<frozen runpy>", line 198, in _run_module_as_main
  File "<frozen runpy>", line 88, in _run_code
  File "C:\Users\SHARS\AppData\Roaming\Python\Python311\site-packages\ipykernel_launcher.py", line 18, in <module>
    app.launch_new_instance()
  File "C:\Users\SHARS\AppData\Roaming\Python\Python311\site-packages\traitlets\config\application.py", line 1075, in launch_instance
    app.start()
  File "C:\Users\SHARS\AppData\Roaming\Python\Python311\site-packages\ipykernel\kernelapp.py", line 739, in start
    self.io_loop.start()
  File "C:\Users\SHARS\AppData\Roaming\Python\Python311\site-packages\tornado\platform\asyncio.py", line 205, in start
    self.asyncio_loop.run_forever()
  File "c:\Users\SHARS\AppData\Local\Programs\Python\Python311\Lib\asyncio\base_events.py", line 608, in run_forever
    self._run_once()
  File "c:\Users\SHARS\AppData\Local\Programs\Python\Python311\Lib\asyncio\base_events.py", line 1936, in _run_once
    handle._run()
  File "c:\Users\SHARS\AppData\Local\Programs\Python\Python311\Lib\asyncio\events.py", line 84, in _run
    self._context.run(self._callback, *self._args)
  File "C:\Users\SHARS\AppData\Roaming\Python\Python311\site-packages\ipykernel\kernelbase.py", line 545, in dispatch_queue
    await self.process_one()
  File "C:\Users\SHARS\AppData\Roaming\Python\Python311\site-packages\ipykernel\kernelbase.py", line 534, in process_one
    await dispatch(*args)
  File "C:\Users\SHARS\AppData\Roaming\Python\Python311\site-packages\ipykernel\kernelbase.py", line 437, in dispatch_shell
    await result
  File "C:\Users\SHARS\AppData\Roaming\Python\Python311\site-packages\ipykernel\ipkernel.py", line 362, in execute_request
    await super().execute_request(stream, ident, parent)
  File "C:\Users\SHARS\AppData\Roaming\Python\Python311\site-packages\ipykernel\kernelbase.py", line 778, in execute_request
    reply_content = await reply_content
  File "C:\Users\SHARS\AppData\Roaming\Python\Python311\site-packages\ipykernel\ipkernel.py", line 449, in do_execute
    res = shell.run_cell(
  File "C:\Users\SHARS\AppData\Roaming\Python\Python311\site-packages\ipykernel\zmqshell.py", line 549, in run_cell
    return super().run_cell(*args, **kwargs)
  File "C:\Users\SHARS\AppData\Roaming\Python\Python311\site-packages\IPython\core\interactiveshell.py", line 3075, in run_cell
    result = self._run_cell(
  File "C:\Users\SHARS\AppData\Roaming\Python\Python311\site-packages\IPython\core\interactiveshell.py", line 3130, in _run_cell
    result = runner(coro)
  File "C:\Users\SHARS\AppData\Roaming\Python\Python311\site-packages\IPython\core\async_helpers.py", line 128, in _pseudo_sync_runner
    coro.send(None)
  File "C:\Users\SHARS\AppData\Roaming\Python\Python311\site-packages\IPython\core\interactiveshell.py", line 3334, in run_cell_async
    has_raised = await self.run_ast_nodes(code_ast.body, cell_name,
  File "C:\Users\SHARS\AppData\Roaming\Python\Python311\site-packages\IPython\core\interactiveshell.py", line 3517, in run_ast_nodes
    if await self.run_code(code, result, async_=asy):
  File "C:\Users\SHARS\AppData\Roaming\Python\Python311\site-packages\IPython\core\interactiveshell.py", line 3577, in run_code
    exec(code_obj, self.user_global_ns, self.user_ns)
  File "C:\Users\SHARS\AppData\Local\Temp\ipykernel_1256\2587197345.py", line 12, in <module>
    wandb.init(project="ResNet18_Resized", name="ResNet18_Scratch_224")
  File "c:\Users\SHARS\AppData\Local\Programs\Python\Python311\Lib\site-packages\wandb\sdk\wandb_init.py", line 1430, in init
    wi.setup_run_log_directory(run_settings)
  File "c:\Users\SHARS\AppData\Local\Programs\Python\Python311\Lib\site-packages\wandb\sdk\wandb_init.py", line 624, in setup_run_log_directory
    self._logger.info(f"Logging user logs to {settings.log_user}")
Message: 'Logging user logs to c:\\Users\\SHARS\\OneDrive\\ë¬¸ì„œ\\GitHub\\assignment-2-HarshvardhanSingh841\\wandb\\run-20250214_181939-2cmxlf90\\logs\\debug.log'
Arguments: ()
--- Logging error ---
Traceback (most recent call last):
  File "c:\Users\SHARS\AppData\Local\Programs\Python\Python311\Lib\logging\__init__.py", line 1113, in emit
    stream.write(msg + self.terminator)
  File "c:\Users\SHARS\AppData\Local\Programs\Python\Python311\Lib\encodings\cp1252.py", line 19, in encode
    return codecs.charmap_encode(input,self.errors,encoding_table)[0]
           ^^^^^^^^^^^^^^^^^^^^^^^^^^^^^^^^^^^^^^^^^^^^^^^^^^^^^^^
UnicodeEncodeError: 'charmap' codec can't encode characters in position 139-140: character maps to <undefined>
Call stack:
  File "<frozen runpy>", line 198, in _run_module_as_main
  File "<frozen runpy>", line 88, in _run_code
  File "C:\Users\SHARS\AppData\Roaming\Python\Python311\site-packages\ipykernel_launcher.py", line 18, in <module>
    app.launch_new_instance()
  File "C:\Users\SHARS\AppData\Roaming\Python\Python311\site-packages\traitlets\config\application.py", line 1075, in launch_instance
    app.start()
  File "C:\Users\SHARS\AppData\Roaming\Python\Python311\site-packages\ipykernel\kernelapp.py", line 739, in start
    self.io_loop.start()
  File "C:\Users\SHARS\AppData\Roaming\Python\Python311\site-packages\tornado\platform\asyncio.py", line 205, in start
    self.asyncio_loop.run_forever()
  File "c:\Users\SHARS\AppData\Local\Programs\Python\Python311\Lib\asyncio\base_events.py", line 608, in run_forever
    self._run_once()
  File "c:\Users\SHARS\AppData\Local\Programs\Python\Python311\Lib\asyncio\base_events.py", line 1936, in _run_once
    handle._run()
  File "c:\Users\SHARS\AppData\Local\Programs\Python\Python311\Lib\asyncio\events.py", line 84, in _run
    self._context.run(self._callback, *self._args)
  File "C:\Users\SHARS\AppData\Roaming\Python\Python311\site-packages\ipykernel\kernelbase.py", line 545, in dispatch_queue
    await self.process_one()
  File "C:\Users\SHARS\AppData\Roaming\Python\Python311\site-packages\ipykernel\kernelbase.py", line 534, in process_one
    await dispatch(*args)
  File "C:\Users\SHARS\AppData\Roaming\Python\Python311\site-packages\ipykernel\kernelbase.py", line 437, in dispatch_shell
    await result
  File "C:\Users\SHARS\AppData\Roaming\Python\Python311\site-packages\ipykernel\ipkernel.py", line 362, in execute_request
    await super().execute_request(stream, ident, parent)
  File "C:\Users\SHARS\AppData\Roaming\Python\Python311\site-packages\ipykernel\kernelbase.py", line 778, in execute_request
    reply_content = await reply_content
  File "C:\Users\SHARS\AppData\Roaming\Python\Python311\site-packages\ipykernel\ipkernel.py", line 449, in do_execute
    res = shell.run_cell(
  File "C:\Users\SHARS\AppData\Roaming\Python\Python311\site-packages\ipykernel\zmqshell.py", line 549, in run_cell
    return super().run_cell(*args, **kwargs)
  File "C:\Users\SHARS\AppData\Roaming\Python\Python311\site-packages\IPython\core\interactiveshell.py", line 3075, in run_cell
    result = self._run_cell(
  File "C:\Users\SHARS\AppData\Roaming\Python\Python311\site-packages\IPython\core\interactiveshell.py", line 3130, in _run_cell
    result = runner(coro)
  File "C:\Users\SHARS\AppData\Roaming\Python\Python311\site-packages\IPython\core\async_helpers.py", line 128, in _pseudo_sync_runner
    coro.send(None)
  File "C:\Users\SHARS\AppData\Roaming\Python\Python311\site-packages\IPython\core\interactiveshell.py", line 3334, in run_cell_async
    has_raised = await self.run_ast_nodes(code_ast.body, cell_name,
  File "C:\Users\SHARS\AppData\Roaming\Python\Python311\site-packages\IPython\core\interactiveshell.py", line 3517, in run_ast_nodes
    if await self.run_code(code, result, async_=asy):
  File "C:\Users\SHARS\AppData\Roaming\Python\Python311\site-packages\IPython\core\interactiveshell.py", line 3577, in run_code
    exec(code_obj, self.user_global_ns, self.user_ns)
  File "C:\Users\SHARS\AppData\Local\Temp\ipykernel_1256\2587197345.py", line 12, in <module>
    wandb.init(project="ResNet18_Resized", name="ResNet18_Scratch_224")
  File "c:\Users\SHARS\AppData\Local\Programs\Python\Python311\Lib\site-packages\wandb\sdk\wandb_init.py", line 1430, in init
    wi.setup_run_log_directory(run_settings)
  File "c:\Users\SHARS\AppData\Local\Programs\Python\Python311\Lib\site-packages\wandb\sdk\wandb_init.py", line 624, in setup_run_log_directory
    self._logger.info(f"Logging user logs to {settings.log_user}")
Message: 'Logging user logs to c:\\Users\\SHARS\\OneDrive\\ë¬¸ì„œ\\GitHub\\assignment-2-HarshvardhanSingh841\\wandb\\run-20250214_181939-2cmxlf90\\logs\\debug.log'
Arguments: ()
--- Logging error ---
Traceback (most recent call last):
  File "c:\Users\SHARS\AppData\Local\Programs\Python\Python311\Lib\logging\__init__.py", line 1113, in emit
    stream.write(msg + self.terminator)
  File "c:\Users\SHARS\AppData\Local\Programs\Python\Python311\Lib\encodings\cp1252.py", line 19, in encode
    return codecs.charmap_encode(input,self.errors,encoding_table)[0]
           ^^^^^^^^^^^^^^^^^^^^^^^^^^^^^^^^^^^^^^^^^^^^^^^^^^^^^^^
UnicodeEncodeError: 'charmap' codec can't encode characters in position 139-140: character maps to <undefined>
Call stack:
  File "<frozen runpy>", line 198, in _run_module_as_main
  File "<frozen runpy>", line 88, in _run_code
  File "C:\Users\SHARS\AppData\Roaming\Python\Python311\site-packages\ipykernel_launcher.py", line 18, in <module>
    app.launch_new_instance()
  File "C:\Users\SHARS\AppData\Roaming\Python\Python311\site-packages\traitlets\config\application.py", line 1075, in launch_instance
    app.start()
  File "C:\Users\SHARS\AppData\Roaming\Python\Python311\site-packages\ipykernel\kernelapp.py", line 739, in start
    self.io_loop.start()
  File "C:\Users\SHARS\AppData\Roaming\Python\Python311\site-packages\tornado\platform\asyncio.py", line 205, in start
    self.asyncio_loop.run_forever()
  File "c:\Users\SHARS\AppData\Local\Programs\Python\Python311\Lib\asyncio\base_events.py", line 608, in run_forever
    self._run_once()
  File "c:\Users\SHARS\AppData\Local\Programs\Python\Python311\Lib\asyncio\base_events.py", line 1936, in _run_once
    handle._run()
  File "c:\Users\SHARS\AppData\Local\Programs\Python\Python311\Lib\asyncio\events.py", line 84, in _run
    self._context.run(self._callback, *self._args)
  File "C:\Users\SHARS\AppData\Roaming\Python\Python311\site-packages\ipykernel\kernelbase.py", line 545, in dispatch_queue
    await self.process_one()
  File "C:\Users\SHARS\AppData\Roaming\Python\Python311\site-packages\ipykernel\kernelbase.py", line 534, in process_one
    await dispatch(*args)
  File "C:\Users\SHARS\AppData\Roaming\Python\Python311\site-packages\ipykernel\kernelbase.py", line 437, in dispatch_shell
    await result
  File "C:\Users\SHARS\AppData\Roaming\Python\Python311\site-packages\ipykernel\ipkernel.py", line 362, in execute_request
    await super().execute_request(stream, ident, parent)
  File "C:\Users\SHARS\AppData\Roaming\Python\Python311\site-packages\ipykernel\kernelbase.py", line 778, in execute_request
    reply_content = await reply_content
  File "C:\Users\SHARS\AppData\Roaming\Python\Python311\site-packages\ipykernel\ipkernel.py", line 449, in do_execute
    res = shell.run_cell(
  File "C:\Users\SHARS\AppData\Roaming\Python\Python311\site-packages\ipykernel\zmqshell.py", line 549, in run_cell
    return super().run_cell(*args, **kwargs)
  File "C:\Users\SHARS\AppData\Roaming\Python\Python311\site-packages\IPython\core\interactiveshell.py", line 3075, in run_cell
    result = self._run_cell(
  File "C:\Users\SHARS\AppData\Roaming\Python\Python311\site-packages\IPython\core\interactiveshell.py", line 3130, in _run_cell
    result = runner(coro)
  File "C:\Users\SHARS\AppData\Roaming\Python\Python311\site-packages\IPython\core\async_helpers.py", line 128, in _pseudo_sync_runner
    coro.send(None)
  File "C:\Users\SHARS\AppData\Roaming\Python\Python311\site-packages\IPython\core\interactiveshell.py", line 3334, in run_cell_async
    has_raised = await self.run_ast_nodes(code_ast.body, cell_name,
  File "C:\Users\SHARS\AppData\Roaming\Python\Python311\site-packages\IPython\core\interactiveshell.py", line 3517, in run_ast_nodes
    if await self.run_code(code, result, async_=asy):
  File "C:\Users\SHARS\AppData\Roaming\Python\Python311\site-packages\IPython\core\interactiveshell.py", line 3577, in run_code
    exec(code_obj, self.user_global_ns, self.user_ns)
  File "C:\Users\SHARS\AppData\Local\Temp\ipykernel_1256\2587197345.py", line 12, in <module>
    wandb.init(project="ResNet18_Resized", name="ResNet18_Scratch_224")
  File "c:\Users\SHARS\AppData\Local\Programs\Python\Python311\Lib\site-packages\wandb\sdk\wandb_init.py", line 1430, in init
    wi.setup_run_log_directory(run_settings)
  File "c:\Users\SHARS\AppData\Local\Programs\Python\Python311\Lib\site-packages\wandb\sdk\wandb_init.py", line 624, in setup_run_log_directory
    self._logger.info(f"Logging user logs to {settings.log_user}")
Message: 'Logging user logs to c:\\Users\\SHARS\\OneDrive\\ë¬¸ì„œ\\GitHub\\assignment-2-HarshvardhanSingh841\\wandb\\run-20250214_181939-2cmxlf90\\logs\\debug.log'
Arguments: ()
--- Logging error ---
Traceback (most recent call last):
  File "c:\Users\SHARS\AppData\Local\Programs\Python\Python311\Lib\logging\__init__.py", line 1113, in emit
    stream.write(msg + self.terminator)
  File "c:\Users\SHARS\AppData\Local\Programs\Python\Python311\Lib\encodings\cp1252.py", line 19, in encode
    return codecs.charmap_encode(input,self.errors,encoding_table)[0]
           ^^^^^^^^^^^^^^^^^^^^^^^^^^^^^^^^^^^^^^^^^^^^^^^^^^^^^^^
UnicodeEncodeError: 'charmap' codec can't encode characters in position 139-140: character maps to <undefined>
Call stack:
  File "<frozen runpy>", line 198, in _run_module_as_main
  File "<frozen runpy>", line 88, in _run_code
  File "C:\Users\SHARS\AppData\Roaming\Python\Python311\site-packages\ipykernel_launcher.py", line 18, in <module>
    app.launch_new_instance()
  File "C:\Users\SHARS\AppData\Roaming\Python\Python311\site-packages\traitlets\config\application.py", line 1075, in launch_instance
    app.start()
  File "C:\Users\SHARS\AppData\Roaming\Python\Python311\site-packages\ipykernel\kernelapp.py", line 739, in start
    self.io_loop.start()
  File "C:\Users\SHARS\AppData\Roaming\Python\Python311\site-packages\tornado\platform\asyncio.py", line 205, in start
    self.asyncio_loop.run_forever()
  File "c:\Users\SHARS\AppData\Local\Programs\Python\Python311\Lib\asyncio\base_events.py", line 608, in run_forever
    self._run_once()
  File "c:\Users\SHARS\AppData\Local\Programs\Python\Python311\Lib\asyncio\base_events.py", line 1936, in _run_once
    handle._run()
  File "c:\Users\SHARS\AppData\Local\Programs\Python\Python311\Lib\asyncio\events.py", line 84, in _run
    self._context.run(self._callback, *self._args)
  File "C:\Users\SHARS\AppData\Roaming\Python\Python311\site-packages\ipykernel\kernelbase.py", line 545, in dispatch_queue
    await self.process_one()
  File "C:\Users\SHARS\AppData\Roaming\Python\Python311\site-packages\ipykernel\kernelbase.py", line 534, in process_one
    await dispatch(*args)
  File "C:\Users\SHARS\AppData\Roaming\Python\Python311\site-packages\ipykernel\kernelbase.py", line 437, in dispatch_shell
    await result
  File "C:\Users\SHARS\AppData\Roaming\Python\Python311\site-packages\ipykernel\ipkernel.py", line 362, in execute_request
    await super().execute_request(stream, ident, parent)
  File "C:\Users\SHARS\AppData\Roaming\Python\Python311\site-packages\ipykernel\kernelbase.py", line 778, in execute_request
    reply_content = await reply_content
  File "C:\Users\SHARS\AppData\Roaming\Python\Python311\site-packages\ipykernel\ipkernel.py", line 449, in do_execute
    res = shell.run_cell(
  File "C:\Users\SHARS\AppData\Roaming\Python\Python311\site-packages\ipykernel\zmqshell.py", line 549, in run_cell
    return super().run_cell(*args, **kwargs)
  File "C:\Users\SHARS\AppData\Roaming\Python\Python311\site-packages\IPython\core\interactiveshell.py", line 3075, in run_cell
    result = self._run_cell(
  File "C:\Users\SHARS\AppData\Roaming\Python\Python311\site-packages\IPython\core\interactiveshell.py", line 3130, in _run_cell
    result = runner(coro)
  File "C:\Users\SHARS\AppData\Roaming\Python\Python311\site-packages\IPython\core\async_helpers.py", line 128, in _pseudo_sync_runner
    coro.send(None)
  File "C:\Users\SHARS\AppData\Roaming\Python\Python311\site-packages\IPython\core\interactiveshell.py", line 3334, in run_cell_async
    has_raised = await self.run_ast_nodes(code_ast.body, cell_name,
  File "C:\Users\SHARS\AppData\Roaming\Python\Python311\site-packages\IPython\core\interactiveshell.py", line 3517, in run_ast_nodes
    if await self.run_code(code, result, async_=asy):
  File "C:\Users\SHARS\AppData\Roaming\Python\Python311\site-packages\IPython\core\interactiveshell.py", line 3577, in run_code
    exec(code_obj, self.user_global_ns, self.user_ns)
  File "C:\Users\SHARS\AppData\Local\Temp\ipykernel_1256\2587197345.py", line 12, in <module>
    wandb.init(project="ResNet18_Resized", name="ResNet18_Scratch_224")
  File "c:\Users\SHARS\AppData\Local\Programs\Python\Python311\Lib\site-packages\wandb\sdk\wandb_init.py", line 1430, in init
    wi.setup_run_log_directory(run_settings)
  File "c:\Users\SHARS\AppData\Local\Programs\Python\Python311\Lib\site-packages\wandb\sdk\wandb_init.py", line 624, in setup_run_log_directory
    self._logger.info(f"Logging user logs to {settings.log_user}")
Message: 'Logging user logs to c:\\Users\\SHARS\\OneDrive\\ë¬¸ì„œ\\GitHub\\assignment-2-HarshvardhanSingh841\\wandb\\run-20250214_181939-2cmxlf90\\logs\\debug.log'
Arguments: ()
--- Logging error ---
Traceback (most recent call last):
  File "c:\Users\SHARS\AppData\Local\Programs\Python\Python311\Lib\logging\__init__.py", line 1113, in emit
    stream.write(msg + self.terminator)
  File "c:\Users\SHARS\AppData\Local\Programs\Python\Python311\Lib\encodings\cp1252.py", line 19, in encode
    return codecs.charmap_encode(input,self.errors,encoding_table)[0]
           ^^^^^^^^^^^^^^^^^^^^^^^^^^^^^^^^^^^^^^^^^^^^^^^^^^^^^^^
UnicodeEncodeError: 'charmap' codec can't encode characters in position 139-140: character maps to <undefined>
Call stack:
  File "<frozen runpy>", line 198, in _run_module_as_main
  File "<frozen runpy>", line 88, in _run_code
  File "C:\Users\SHARS\AppData\Roaming\Python\Python311\site-packages\ipykernel_launcher.py", line 18, in <module>
    app.launch_new_instance()
  File "C:\Users\SHARS\AppData\Roaming\Python\Python311\site-packages\traitlets\config\application.py", line 1075, in launch_instance
    app.start()
  File "C:\Users\SHARS\AppData\Roaming\Python\Python311\site-packages\ipykernel\kernelapp.py", line 739, in start
    self.io_loop.start()
  File "C:\Users\SHARS\AppData\Roaming\Python\Python311\site-packages\tornado\platform\asyncio.py", line 205, in start
    self.asyncio_loop.run_forever()
  File "c:\Users\SHARS\AppData\Local\Programs\Python\Python311\Lib\asyncio\base_events.py", line 608, in run_forever
    self._run_once()
  File "c:\Users\SHARS\AppData\Local\Programs\Python\Python311\Lib\asyncio\base_events.py", line 1936, in _run_once
    handle._run()
  File "c:\Users\SHARS\AppData\Local\Programs\Python\Python311\Lib\asyncio\events.py", line 84, in _run
    self._context.run(self._callback, *self._args)
  File "C:\Users\SHARS\AppData\Roaming\Python\Python311\site-packages\ipykernel\kernelbase.py", line 545, in dispatch_queue
    await self.process_one()
  File "C:\Users\SHARS\AppData\Roaming\Python\Python311\site-packages\ipykernel\kernelbase.py", line 534, in process_one
    await dispatch(*args)
  File "C:\Users\SHARS\AppData\Roaming\Python\Python311\site-packages\ipykernel\kernelbase.py", line 437, in dispatch_shell
    await result
  File "C:\Users\SHARS\AppData\Roaming\Python\Python311\site-packages\ipykernel\ipkernel.py", line 362, in execute_request
    await super().execute_request(stream, ident, parent)
  File "C:\Users\SHARS\AppData\Roaming\Python\Python311\site-packages\ipykernel\kernelbase.py", line 778, in execute_request
    reply_content = await reply_content
  File "C:\Users\SHARS\AppData\Roaming\Python\Python311\site-packages\ipykernel\ipkernel.py", line 449, in do_execute
    res = shell.run_cell(
  File "C:\Users\SHARS\AppData\Roaming\Python\Python311\site-packages\ipykernel\zmqshell.py", line 549, in run_cell
    return super().run_cell(*args, **kwargs)
  File "C:\Users\SHARS\AppData\Roaming\Python\Python311\site-packages\IPython\core\interactiveshell.py", line 3075, in run_cell
    result = self._run_cell(
  File "C:\Users\SHARS\AppData\Roaming\Python\Python311\site-packages\IPython\core\interactiveshell.py", line 3130, in _run_cell
    result = runner(coro)
  File "C:\Users\SHARS\AppData\Roaming\Python\Python311\site-packages\IPython\core\async_helpers.py", line 128, in _pseudo_sync_runner
    coro.send(None)
  File "C:\Users\SHARS\AppData\Roaming\Python\Python311\site-packages\IPython\core\interactiveshell.py", line 3334, in run_cell_async
    has_raised = await self.run_ast_nodes(code_ast.body, cell_name,
  File "C:\Users\SHARS\AppData\Roaming\Python\Python311\site-packages\IPython\core\interactiveshell.py", line 3517, in run_ast_nodes
    if await self.run_code(code, result, async_=asy):
  File "C:\Users\SHARS\AppData\Roaming\Python\Python311\site-packages\IPython\core\interactiveshell.py", line 3577, in run_code
    exec(code_obj, self.user_global_ns, self.user_ns)
  File "C:\Users\SHARS\AppData\Local\Temp\ipykernel_1256\2587197345.py", line 12, in <module>
    wandb.init(project="ResNet18_Resized", name="ResNet18_Scratch_224")
  File "c:\Users\SHARS\AppData\Local\Programs\Python\Python311\Lib\site-packages\wandb\sdk\wandb_init.py", line 1430, in init
    wi.setup_run_log_directory(run_settings)
  File "c:\Users\SHARS\AppData\Local\Programs\Python\Python311\Lib\site-packages\wandb\sdk\wandb_init.py", line 624, in setup_run_log_directory
    self._logger.info(f"Logging user logs to {settings.log_user}")
Message: 'Logging user logs to c:\\Users\\SHARS\\OneDrive\\ë¬¸ì„œ\\GitHub\\assignment-2-HarshvardhanSingh841\\wandb\\run-20250214_181939-2cmxlf90\\logs\\debug.log'
Arguments: ()
--- Logging error ---
Traceback (most recent call last):
  File "c:\Users\SHARS\AppData\Local\Programs\Python\Python311\Lib\logging\__init__.py", line 1113, in emit
    stream.write(msg + self.terminator)
  File "c:\Users\SHARS\AppData\Local\Programs\Python\Python311\Lib\encodings\cp1252.py", line 19, in encode
    return codecs.charmap_encode(input,self.errors,encoding_table)[0]
           ^^^^^^^^^^^^^^^^^^^^^^^^^^^^^^^^^^^^^^^^^^^^^^^^^^^^^^^
UnicodeEncodeError: 'charmap' codec can't encode characters in position 143-144: character maps to <undefined>
Call stack:
  File "<frozen runpy>", line 198, in _run_module_as_main
  File "<frozen runpy>", line 88, in _run_code
  File "C:\Users\SHARS\AppData\Roaming\Python\Python311\site-packages\ipykernel_launcher.py", line 18, in <module>
    app.launch_new_instance()
  File "C:\Users\SHARS\AppData\Roaming\Python\Python311\site-packages\traitlets\config\application.py", line 1075, in launch_instance
    app.start()
  File "C:\Users\SHARS\AppData\Roaming\Python\Python311\site-packages\ipykernel\kernelapp.py", line 739, in start
    self.io_loop.start()
  File "C:\Users\SHARS\AppData\Roaming\Python\Python311\site-packages\tornado\platform\asyncio.py", line 205, in start
    self.asyncio_loop.run_forever()
  File "c:\Users\SHARS\AppData\Local\Programs\Python\Python311\Lib\asyncio\base_events.py", line 608, in run_forever
    self._run_once()
  File "c:\Users\SHARS\AppData\Local\Programs\Python\Python311\Lib\asyncio\base_events.py", line 1936, in _run_once
    handle._run()
  File "c:\Users\SHARS\AppData\Local\Programs\Python\Python311\Lib\asyncio\events.py", line 84, in _run
    self._context.run(self._callback, *self._args)
  File "C:\Users\SHARS\AppData\Roaming\Python\Python311\site-packages\ipykernel\kernelbase.py", line 545, in dispatch_queue
    await self.process_one()
  File "C:\Users\SHARS\AppData\Roaming\Python\Python311\site-packages\ipykernel\kernelbase.py", line 534, in process_one
    await dispatch(*args)
  File "C:\Users\SHARS\AppData\Roaming\Python\Python311\site-packages\ipykernel\kernelbase.py", line 437, in dispatch_shell
    await result
  File "C:\Users\SHARS\AppData\Roaming\Python\Python311\site-packages\ipykernel\ipkernel.py", line 362, in execute_request
    await super().execute_request(stream, ident, parent)
  File "C:\Users\SHARS\AppData\Roaming\Python\Python311\site-packages\ipykernel\kernelbase.py", line 778, in execute_request
    reply_content = await reply_content
  File "C:\Users\SHARS\AppData\Roaming\Python\Python311\site-packages\ipykernel\ipkernel.py", line 449, in do_execute
    res = shell.run_cell(
  File "C:\Users\SHARS\AppData\Roaming\Python\Python311\site-packages\ipykernel\zmqshell.py", line 549, in run_cell
    return super().run_cell(*args, **kwargs)
  File "C:\Users\SHARS\AppData\Roaming\Python\Python311\site-packages\IPython\core\interactiveshell.py", line 3075, in run_cell
    result = self._run_cell(
  File "C:\Users\SHARS\AppData\Roaming\Python\Python311\site-packages\IPython\core\interactiveshell.py", line 3130, in _run_cell
    result = runner(coro)
  File "C:\Users\SHARS\AppData\Roaming\Python\Python311\site-packages\IPython\core\async_helpers.py", line 128, in _pseudo_sync_runner
    coro.send(None)
  File "C:\Users\SHARS\AppData\Roaming\Python\Python311\site-packages\IPython\core\interactiveshell.py", line 3334, in run_cell_async
    has_raised = await self.run_ast_nodes(code_ast.body, cell_name,
  File "C:\Users\SHARS\AppData\Roaming\Python\Python311\site-packages\IPython\core\interactiveshell.py", line 3517, in run_ast_nodes
    if await self.run_code(code, result, async_=asy):
  File "C:\Users\SHARS\AppData\Roaming\Python\Python311\site-packages\IPython\core\interactiveshell.py", line 3577, in run_code
    exec(code_obj, self.user_global_ns, self.user_ns)
  File "C:\Users\SHARS\AppData\Local\Temp\ipykernel_1256\2587197345.py", line 12, in <module>
    wandb.init(project="ResNet18_Resized", name="ResNet18_Scratch_224")
  File "c:\Users\SHARS\AppData\Local\Programs\Python\Python311\Lib\site-packages\wandb\sdk\wandb_init.py", line 1430, in init
    wi.setup_run_log_directory(run_settings)
  File "c:\Users\SHARS\AppData\Local\Programs\Python\Python311\Lib\site-packages\wandb\sdk\wandb_init.py", line 625, in setup_run_log_directory
    self._logger.info(f"Logging internal logs to {settings.log_internal}")
Message: 'Logging internal logs to c:\\Users\\SHARS\\OneDrive\\ë¬¸ì„œ\\GitHub\\assignment-2-HarshvardhanSingh841\\wandb\\run-20250214_181939-2cmxlf90\\logs\\debug-internal.log'
Arguments: ()
--- Logging error ---
Traceback (most recent call last):
  File "c:\Users\SHARS\AppData\Local\Programs\Python\Python311\Lib\logging\__init__.py", line 1113, in emit
    stream.write(msg + self.terminator)
  File "c:\Users\SHARS\AppData\Local\Programs\Python\Python311\Lib\encodings\cp1252.py", line 19, in encode
    return codecs.charmap_encode(input,self.errors,encoding_table)[0]
           ^^^^^^^^^^^^^^^^^^^^^^^^^^^^^^^^^^^^^^^^^^^^^^^^^^^^^^^
UnicodeEncodeError: 'charmap' codec can't encode characters in position 143-144: character maps to <undefined>
Call stack:
  File "<frozen runpy>", line 198, in _run_module_as_main
  File "<frozen runpy>", line 88, in _run_code
  File "C:\Users\SHARS\AppData\Roaming\Python\Python311\site-packages\ipykernel_launcher.py", line 18, in <module>
    app.launch_new_instance()
  File "C:\Users\SHARS\AppData\Roaming\Python\Python311\site-packages\traitlets\config\application.py", line 1075, in launch_instance
    app.start()
  File "C:\Users\SHARS\AppData\Roaming\Python\Python311\site-packages\ipykernel\kernelapp.py", line 739, in start
    self.io_loop.start()
  File "C:\Users\SHARS\AppData\Roaming\Python\Python311\site-packages\tornado\platform\asyncio.py", line 205, in start
    self.asyncio_loop.run_forever()
  File "c:\Users\SHARS\AppData\Local\Programs\Python\Python311\Lib\asyncio\base_events.py", line 608, in run_forever
    self._run_once()
  File "c:\Users\SHARS\AppData\Local\Programs\Python\Python311\Lib\asyncio\base_events.py", line 1936, in _run_once
    handle._run()
  File "c:\Users\SHARS\AppData\Local\Programs\Python\Python311\Lib\asyncio\events.py", line 84, in _run
    self._context.run(self._callback, *self._args)
  File "C:\Users\SHARS\AppData\Roaming\Python\Python311\site-packages\ipykernel\kernelbase.py", line 545, in dispatch_queue
    await self.process_one()
  File "C:\Users\SHARS\AppData\Roaming\Python\Python311\site-packages\ipykernel\kernelbase.py", line 534, in process_one
    await dispatch(*args)
  File "C:\Users\SHARS\AppData\Roaming\Python\Python311\site-packages\ipykernel\kernelbase.py", line 437, in dispatch_shell
    await result
  File "C:\Users\SHARS\AppData\Roaming\Python\Python311\site-packages\ipykernel\ipkernel.py", line 362, in execute_request
    await super().execute_request(stream, ident, parent)
  File "C:\Users\SHARS\AppData\Roaming\Python\Python311\site-packages\ipykernel\kernelbase.py", line 778, in execute_request
    reply_content = await reply_content
  File "C:\Users\SHARS\AppData\Roaming\Python\Python311\site-packages\ipykernel\ipkernel.py", line 449, in do_execute
    res = shell.run_cell(
  File "C:\Users\SHARS\AppData\Roaming\Python\Python311\site-packages\ipykernel\zmqshell.py", line 549, in run_cell
    return super().run_cell(*args, **kwargs)
  File "C:\Users\SHARS\AppData\Roaming\Python\Python311\site-packages\IPython\core\interactiveshell.py", line 3075, in run_cell
    result = self._run_cell(
  File "C:\Users\SHARS\AppData\Roaming\Python\Python311\site-packages\IPython\core\interactiveshell.py", line 3130, in _run_cell
    result = runner(coro)
  File "C:\Users\SHARS\AppData\Roaming\Python\Python311\site-packages\IPython\core\async_helpers.py", line 128, in _pseudo_sync_runner
    coro.send(None)
  File "C:\Users\SHARS\AppData\Roaming\Python\Python311\site-packages\IPython\core\interactiveshell.py", line 3334, in run_cell_async
    has_raised = await self.run_ast_nodes(code_ast.body, cell_name,
  File "C:\Users\SHARS\AppData\Roaming\Python\Python311\site-packages\IPython\core\interactiveshell.py", line 3517, in run_ast_nodes
    if await self.run_code(code, result, async_=asy):
  File "C:\Users\SHARS\AppData\Roaming\Python\Python311\site-packages\IPython\core\interactiveshell.py", line 3577, in run_code
    exec(code_obj, self.user_global_ns, self.user_ns)
  File "C:\Users\SHARS\AppData\Local\Temp\ipykernel_1256\2587197345.py", line 12, in <module>
    wandb.init(project="ResNet18_Resized", name="ResNet18_Scratch_224")
  File "c:\Users\SHARS\AppData\Local\Programs\Python\Python311\Lib\site-packages\wandb\sdk\wandb_init.py", line 1430, in init
    wi.setup_run_log_directory(run_settings)
  File "c:\Users\SHARS\AppData\Local\Programs\Python\Python311\Lib\site-packages\wandb\sdk\wandb_init.py", line 625, in setup_run_log_directory
    self._logger.info(f"Logging internal logs to {settings.log_internal}")
Message: 'Logging internal logs to c:\\Users\\SHARS\\OneDrive\\ë¬¸ì„œ\\GitHub\\assignment-2-HarshvardhanSingh841\\wandb\\run-20250214_181939-2cmxlf90\\logs\\debug-internal.log'
Arguments: ()
--- Logging error ---
Traceback (most recent call last):
  File "c:\Users\SHARS\AppData\Local\Programs\Python\Python311\Lib\logging\__init__.py", line 1113, in emit
    stream.write(msg + self.terminator)
  File "c:\Users\SHARS\AppData\Local\Programs\Python\Python311\Lib\encodings\cp1252.py", line 19, in encode
    return codecs.charmap_encode(input,self.errors,encoding_table)[0]
           ^^^^^^^^^^^^^^^^^^^^^^^^^^^^^^^^^^^^^^^^^^^^^^^^^^^^^^^
UnicodeEncodeError: 'charmap' codec can't encode characters in position 143-144: character maps to <undefined>
Call stack:
  File "<frozen runpy>", line 198, in _run_module_as_main
  File "<frozen runpy>", line 88, in _run_code
  File "C:\Users\SHARS\AppData\Roaming\Python\Python311\site-packages\ipykernel_launcher.py", line 18, in <module>
    app.launch_new_instance()
  File "C:\Users\SHARS\AppData\Roaming\Python\Python311\site-packages\traitlets\config\application.py", line 1075, in launch_instance
    app.start()
  File "C:\Users\SHARS\AppData\Roaming\Python\Python311\site-packages\ipykernel\kernelapp.py", line 739, in start
    self.io_loop.start()
  File "C:\Users\SHARS\AppData\Roaming\Python\Python311\site-packages\tornado\platform\asyncio.py", line 205, in start
    self.asyncio_loop.run_forever()
  File "c:\Users\SHARS\AppData\Local\Programs\Python\Python311\Lib\asyncio\base_events.py", line 608, in run_forever
    self._run_once()
  File "c:\Users\SHARS\AppData\Local\Programs\Python\Python311\Lib\asyncio\base_events.py", line 1936, in _run_once
    handle._run()
  File "c:\Users\SHARS\AppData\Local\Programs\Python\Python311\Lib\asyncio\events.py", line 84, in _run
    self._context.run(self._callback, *self._args)
  File "C:\Users\SHARS\AppData\Roaming\Python\Python311\site-packages\ipykernel\kernelbase.py", line 545, in dispatch_queue
    await self.process_one()
  File "C:\Users\SHARS\AppData\Roaming\Python\Python311\site-packages\ipykernel\kernelbase.py", line 534, in process_one
    await dispatch(*args)
  File "C:\Users\SHARS\AppData\Roaming\Python\Python311\site-packages\ipykernel\kernelbase.py", line 437, in dispatch_shell
    await result
  File "C:\Users\SHARS\AppData\Roaming\Python\Python311\site-packages\ipykernel\ipkernel.py", line 362, in execute_request
    await super().execute_request(stream, ident, parent)
  File "C:\Users\SHARS\AppData\Roaming\Python\Python311\site-packages\ipykernel\kernelbase.py", line 778, in execute_request
    reply_content = await reply_content
  File "C:\Users\SHARS\AppData\Roaming\Python\Python311\site-packages\ipykernel\ipkernel.py", line 449, in do_execute
    res = shell.run_cell(
  File "C:\Users\SHARS\AppData\Roaming\Python\Python311\site-packages\ipykernel\zmqshell.py", line 549, in run_cell
    return super().run_cell(*args, **kwargs)
  File "C:\Users\SHARS\AppData\Roaming\Python\Python311\site-packages\IPython\core\interactiveshell.py", line 3075, in run_cell
    result = self._run_cell(
  File "C:\Users\SHARS\AppData\Roaming\Python\Python311\site-packages\IPython\core\interactiveshell.py", line 3130, in _run_cell
    result = runner(coro)
  File "C:\Users\SHARS\AppData\Roaming\Python\Python311\site-packages\IPython\core\async_helpers.py", line 128, in _pseudo_sync_runner
    coro.send(None)
  File "C:\Users\SHARS\AppData\Roaming\Python\Python311\site-packages\IPython\core\interactiveshell.py", line 3334, in run_cell_async
    has_raised = await self.run_ast_nodes(code_ast.body, cell_name,
  File "C:\Users\SHARS\AppData\Roaming\Python\Python311\site-packages\IPython\core\interactiveshell.py", line 3517, in run_ast_nodes
    if await self.run_code(code, result, async_=asy):
  File "C:\Users\SHARS\AppData\Roaming\Python\Python311\site-packages\IPython\core\interactiveshell.py", line 3577, in run_code
    exec(code_obj, self.user_global_ns, self.user_ns)
  File "C:\Users\SHARS\AppData\Local\Temp\ipykernel_1256\2587197345.py", line 12, in <module>
    wandb.init(project="ResNet18_Resized", name="ResNet18_Scratch_224")
  File "c:\Users\SHARS\AppData\Local\Programs\Python\Python311\Lib\site-packages\wandb\sdk\wandb_init.py", line 1430, in init
    wi.setup_run_log_directory(run_settings)
  File "c:\Users\SHARS\AppData\Local\Programs\Python\Python311\Lib\site-packages\wandb\sdk\wandb_init.py", line 625, in setup_run_log_directory
    self._logger.info(f"Logging internal logs to {settings.log_internal}")
Message: 'Logging internal logs to c:\\Users\\SHARS\\OneDrive\\ë¬¸ì„œ\\GitHub\\assignment-2-HarshvardhanSingh841\\wandb\\run-20250214_181939-2cmxlf90\\logs\\debug-internal.log'
Arguments: ()
--- Logging error ---
Traceback (most recent call last):
  File "c:\Users\SHARS\AppData\Local\Programs\Python\Python311\Lib\logging\__init__.py", line 1113, in emit
    stream.write(msg + self.terminator)
  File "c:\Users\SHARS\AppData\Local\Programs\Python\Python311\Lib\encodings\cp1252.py", line 19, in encode
    return codecs.charmap_encode(input,self.errors,encoding_table)[0]
           ^^^^^^^^^^^^^^^^^^^^^^^^^^^^^^^^^^^^^^^^^^^^^^^^^^^^^^^
UnicodeEncodeError: 'charmap' codec can't encode characters in position 143-144: character maps to <undefined>
Call stack:
  File "<frozen runpy>", line 198, in _run_module_as_main
  File "<frozen runpy>", line 88, in _run_code
  File "C:\Users\SHARS\AppData\Roaming\Python\Python311\site-packages\ipykernel_launcher.py", line 18, in <module>
    app.launch_new_instance()
  File "C:\Users\SHARS\AppData\Roaming\Python\Python311\site-packages\traitlets\config\application.py", line 1075, in launch_instance
    app.start()
  File "C:\Users\SHARS\AppData\Roaming\Python\Python311\site-packages\ipykernel\kernelapp.py", line 739, in start
    self.io_loop.start()
  File "C:\Users\SHARS\AppData\Roaming\Python\Python311\site-packages\tornado\platform\asyncio.py", line 205, in start
    self.asyncio_loop.run_forever()
  File "c:\Users\SHARS\AppData\Local\Programs\Python\Python311\Lib\asyncio\base_events.py", line 608, in run_forever
    self._run_once()
  File "c:\Users\SHARS\AppData\Local\Programs\Python\Python311\Lib\asyncio\base_events.py", line 1936, in _run_once
    handle._run()
  File "c:\Users\SHARS\AppData\Local\Programs\Python\Python311\Lib\asyncio\events.py", line 84, in _run
    self._context.run(self._callback, *self._args)
  File "C:\Users\SHARS\AppData\Roaming\Python\Python311\site-packages\ipykernel\kernelbase.py", line 545, in dispatch_queue
    await self.process_one()
  File "C:\Users\SHARS\AppData\Roaming\Python\Python311\site-packages\ipykernel\kernelbase.py", line 534, in process_one
    await dispatch(*args)
  File "C:\Users\SHARS\AppData\Roaming\Python\Python311\site-packages\ipykernel\kernelbase.py", line 437, in dispatch_shell
    await result
  File "C:\Users\SHARS\AppData\Roaming\Python\Python311\site-packages\ipykernel\ipkernel.py", line 362, in execute_request
    await super().execute_request(stream, ident, parent)
  File "C:\Users\SHARS\AppData\Roaming\Python\Python311\site-packages\ipykernel\kernelbase.py", line 778, in execute_request
    reply_content = await reply_content
  File "C:\Users\SHARS\AppData\Roaming\Python\Python311\site-packages\ipykernel\ipkernel.py", line 449, in do_execute
    res = shell.run_cell(
  File "C:\Users\SHARS\AppData\Roaming\Python\Python311\site-packages\ipykernel\zmqshell.py", line 549, in run_cell
    return super().run_cell(*args, **kwargs)
  File "C:\Users\SHARS\AppData\Roaming\Python\Python311\site-packages\IPython\core\interactiveshell.py", line 3075, in run_cell
    result = self._run_cell(
  File "C:\Users\SHARS\AppData\Roaming\Python\Python311\site-packages\IPython\core\interactiveshell.py", line 3130, in _run_cell
    result = runner(coro)
  File "C:\Users\SHARS\AppData\Roaming\Python\Python311\site-packages\IPython\core\async_helpers.py", line 128, in _pseudo_sync_runner
    coro.send(None)
  File "C:\Users\SHARS\AppData\Roaming\Python\Python311\site-packages\IPython\core\interactiveshell.py", line 3334, in run_cell_async
    has_raised = await self.run_ast_nodes(code_ast.body, cell_name,
  File "C:\Users\SHARS\AppData\Roaming\Python\Python311\site-packages\IPython\core\interactiveshell.py", line 3517, in run_ast_nodes
    if await self.run_code(code, result, async_=asy):
  File "C:\Users\SHARS\AppData\Roaming\Python\Python311\site-packages\IPython\core\interactiveshell.py", line 3577, in run_code
    exec(code_obj, self.user_global_ns, self.user_ns)
  File "C:\Users\SHARS\AppData\Local\Temp\ipykernel_1256\2587197345.py", line 12, in <module>
    wandb.init(project="ResNet18_Resized", name="ResNet18_Scratch_224")
  File "c:\Users\SHARS\AppData\Local\Programs\Python\Python311\Lib\site-packages\wandb\sdk\wandb_init.py", line 1430, in init
    wi.setup_run_log_directory(run_settings)
  File "c:\Users\SHARS\AppData\Local\Programs\Python\Python311\Lib\site-packages\wandb\sdk\wandb_init.py", line 625, in setup_run_log_directory
    self._logger.info(f"Logging internal logs to {settings.log_internal}")
Message: 'Logging internal logs to c:\\Users\\SHARS\\OneDrive\\ë¬¸ì„œ\\GitHub\\assignment-2-HarshvardhanSingh841\\wandb\\run-20250214_181939-2cmxlf90\\logs\\debug-internal.log'
Arguments: ()
--- Logging error ---
Traceback (most recent call last):
  File "c:\Users\SHARS\AppData\Local\Programs\Python\Python311\Lib\logging\__init__.py", line 1113, in emit
    stream.write(msg + self.terminator)
  File "c:\Users\SHARS\AppData\Local\Programs\Python\Python311\Lib\encodings\cp1252.py", line 19, in encode
    return codecs.charmap_encode(input,self.errors,encoding_table)[0]
           ^^^^^^^^^^^^^^^^^^^^^^^^^^^^^^^^^^^^^^^^^^^^^^^^^^^^^^^
UnicodeEncodeError: 'charmap' codec can't encode characters in position 143-144: character maps to <undefined>
Call stack:
  File "<frozen runpy>", line 198, in _run_module_as_main
  File "<frozen runpy>", line 88, in _run_code
  File "C:\Users\SHARS\AppData\Roaming\Python\Python311\site-packages\ipykernel_launcher.py", line 18, in <module>
    app.launch_new_instance()
  File "C:\Users\SHARS\AppData\Roaming\Python\Python311\site-packages\traitlets\config\application.py", line 1075, in launch_instance
    app.start()
  File "C:\Users\SHARS\AppData\Roaming\Python\Python311\site-packages\ipykernel\kernelapp.py", line 739, in start
    self.io_loop.start()
  File "C:\Users\SHARS\AppData\Roaming\Python\Python311\site-packages\tornado\platform\asyncio.py", line 205, in start
    self.asyncio_loop.run_forever()
  File "c:\Users\SHARS\AppData\Local\Programs\Python\Python311\Lib\asyncio\base_events.py", line 608, in run_forever
    self._run_once()
  File "c:\Users\SHARS\AppData\Local\Programs\Python\Python311\Lib\asyncio\base_events.py", line 1936, in _run_once
    handle._run()
  File "c:\Users\SHARS\AppData\Local\Programs\Python\Python311\Lib\asyncio\events.py", line 84, in _run
    self._context.run(self._callback, *self._args)
  File "C:\Users\SHARS\AppData\Roaming\Python\Python311\site-packages\ipykernel\kernelbase.py", line 545, in dispatch_queue
    await self.process_one()
  File "C:\Users\SHARS\AppData\Roaming\Python\Python311\site-packages\ipykernel\kernelbase.py", line 534, in process_one
    await dispatch(*args)
  File "C:\Users\SHARS\AppData\Roaming\Python\Python311\site-packages\ipykernel\kernelbase.py", line 437, in dispatch_shell
    await result
  File "C:\Users\SHARS\AppData\Roaming\Python\Python311\site-packages\ipykernel\ipkernel.py", line 362, in execute_request
    await super().execute_request(stream, ident, parent)
  File "C:\Users\SHARS\AppData\Roaming\Python\Python311\site-packages\ipykernel\kernelbase.py", line 778, in execute_request
    reply_content = await reply_content
  File "C:\Users\SHARS\AppData\Roaming\Python\Python311\site-packages\ipykernel\ipkernel.py", line 449, in do_execute
    res = shell.run_cell(
  File "C:\Users\SHARS\AppData\Roaming\Python\Python311\site-packages\ipykernel\zmqshell.py", line 549, in run_cell
    return super().run_cell(*args, **kwargs)
  File "C:\Users\SHARS\AppData\Roaming\Python\Python311\site-packages\IPython\core\interactiveshell.py", line 3075, in run_cell
    result = self._run_cell(
  File "C:\Users\SHARS\AppData\Roaming\Python\Python311\site-packages\IPython\core\interactiveshell.py", line 3130, in _run_cell
    result = runner(coro)
  File "C:\Users\SHARS\AppData\Roaming\Python\Python311\site-packages\IPython\core\async_helpers.py", line 128, in _pseudo_sync_runner
    coro.send(None)
  File "C:\Users\SHARS\AppData\Roaming\Python\Python311\site-packages\IPython\core\interactiveshell.py", line 3334, in run_cell_async
    has_raised = await self.run_ast_nodes(code_ast.body, cell_name,
  File "C:\Users\SHARS\AppData\Roaming\Python\Python311\site-packages\IPython\core\interactiveshell.py", line 3517, in run_ast_nodes
    if await self.run_code(code, result, async_=asy):
  File "C:\Users\SHARS\AppData\Roaming\Python\Python311\site-packages\IPython\core\interactiveshell.py", line 3577, in run_code
    exec(code_obj, self.user_global_ns, self.user_ns)
  File "C:\Users\SHARS\AppData\Local\Temp\ipykernel_1256\2587197345.py", line 12, in <module>
    wandb.init(project="ResNet18_Resized", name="ResNet18_Scratch_224")
  File "c:\Users\SHARS\AppData\Local\Programs\Python\Python311\Lib\site-packages\wandb\sdk\wandb_init.py", line 1430, in init
    wi.setup_run_log_directory(run_settings)
  File "c:\Users\SHARS\AppData\Local\Programs\Python\Python311\Lib\site-packages\wandb\sdk\wandb_init.py", line 625, in setup_run_log_directory
    self._logger.info(f"Logging internal logs to {settings.log_internal}")
Message: 'Logging internal logs to c:\\Users\\SHARS\\OneDrive\\ë¬¸ì„œ\\GitHub\\assignment-2-HarshvardhanSingh841\\wandb\\run-20250214_181939-2cmxlf90\\logs\\debug-internal.log'
Arguments: ()
--- Logging error ---
Traceback (most recent call last):
  File "c:\Users\SHARS\AppData\Local\Programs\Python\Python311\Lib\logging\__init__.py", line 1113, in emit
    stream.write(msg + self.terminator)
  File "c:\Users\SHARS\AppData\Local\Programs\Python\Python311\Lib\encodings\cp1252.py", line 19, in encode
    return codecs.charmap_encode(input,self.errors,encoding_table)[0]
           ^^^^^^^^^^^^^^^^^^^^^^^^^^^^^^^^^^^^^^^^^^^^^^^^^^^^^^^
UnicodeEncodeError: 'charmap' codec can't encode characters in position 143-144: character maps to <undefined>
Call stack:
  File "<frozen runpy>", line 198, in _run_module_as_main
  File "<frozen runpy>", line 88, in _run_code
  File "C:\Users\SHARS\AppData\Roaming\Python\Python311\site-packages\ipykernel_launcher.py", line 18, in <module>
    app.launch_new_instance()
  File "C:\Users\SHARS\AppData\Roaming\Python\Python311\site-packages\traitlets\config\application.py", line 1075, in launch_instance
    app.start()
  File "C:\Users\SHARS\AppData\Roaming\Python\Python311\site-packages\ipykernel\kernelapp.py", line 739, in start
    self.io_loop.start()
  File "C:\Users\SHARS\AppData\Roaming\Python\Python311\site-packages\tornado\platform\asyncio.py", line 205, in start
    self.asyncio_loop.run_forever()
  File "c:\Users\SHARS\AppData\Local\Programs\Python\Python311\Lib\asyncio\base_events.py", line 608, in run_forever
    self._run_once()
  File "c:\Users\SHARS\AppData\Local\Programs\Python\Python311\Lib\asyncio\base_events.py", line 1936, in _run_once
    handle._run()
  File "c:\Users\SHARS\AppData\Local\Programs\Python\Python311\Lib\asyncio\events.py", line 84, in _run
    self._context.run(self._callback, *self._args)
  File "C:\Users\SHARS\AppData\Roaming\Python\Python311\site-packages\ipykernel\kernelbase.py", line 545, in dispatch_queue
    await self.process_one()
  File "C:\Users\SHARS\AppData\Roaming\Python\Python311\site-packages\ipykernel\kernelbase.py", line 534, in process_one
    await dispatch(*args)
  File "C:\Users\SHARS\AppData\Roaming\Python\Python311\site-packages\ipykernel\kernelbase.py", line 437, in dispatch_shell
    await result
  File "C:\Users\SHARS\AppData\Roaming\Python\Python311\site-packages\ipykernel\ipkernel.py", line 362, in execute_request
    await super().execute_request(stream, ident, parent)
  File "C:\Users\SHARS\AppData\Roaming\Python\Python311\site-packages\ipykernel\kernelbase.py", line 778, in execute_request
    reply_content = await reply_content
  File "C:\Users\SHARS\AppData\Roaming\Python\Python311\site-packages\ipykernel\ipkernel.py", line 449, in do_execute
    res = shell.run_cell(
  File "C:\Users\SHARS\AppData\Roaming\Python\Python311\site-packages\ipykernel\zmqshell.py", line 549, in run_cell
    return super().run_cell(*args, **kwargs)
  File "C:\Users\SHARS\AppData\Roaming\Python\Python311\site-packages\IPython\core\interactiveshell.py", line 3075, in run_cell
    result = self._run_cell(
  File "C:\Users\SHARS\AppData\Roaming\Python\Python311\site-packages\IPython\core\interactiveshell.py", line 3130, in _run_cell
    result = runner(coro)
  File "C:\Users\SHARS\AppData\Roaming\Python\Python311\site-packages\IPython\core\async_helpers.py", line 128, in _pseudo_sync_runner
    coro.send(None)
  File "C:\Users\SHARS\AppData\Roaming\Python\Python311\site-packages\IPython\core\interactiveshell.py", line 3334, in run_cell_async
    has_raised = await self.run_ast_nodes(code_ast.body, cell_name,
  File "C:\Users\SHARS\AppData\Roaming\Python\Python311\site-packages\IPython\core\interactiveshell.py", line 3517, in run_ast_nodes
    if await self.run_code(code, result, async_=asy):
  File "C:\Users\SHARS\AppData\Roaming\Python\Python311\site-packages\IPython\core\interactiveshell.py", line 3577, in run_code
    exec(code_obj, self.user_global_ns, self.user_ns)
  File "C:\Users\SHARS\AppData\Local\Temp\ipykernel_1256\2587197345.py", line 12, in <module>
    wandb.init(project="ResNet18_Resized", name="ResNet18_Scratch_224")
  File "c:\Users\SHARS\AppData\Local\Programs\Python\Python311\Lib\site-packages\wandb\sdk\wandb_init.py", line 1430, in init
    wi.setup_run_log_directory(run_settings)
  File "c:\Users\SHARS\AppData\Local\Programs\Python\Python311\Lib\site-packages\wandb\sdk\wandb_init.py", line 625, in setup_run_log_directory
    self._logger.info(f"Logging internal logs to {settings.log_internal}")
Message: 'Logging internal logs to c:\\Users\\SHARS\\OneDrive\\ë¬¸ì„œ\\GitHub\\assignment-2-HarshvardhanSingh841\\wandb\\run-20250214_181939-2cmxlf90\\logs\\debug-internal.log'
Arguments: ()
ðŸš€ Training ResNet18 from Scratch (224Ã—224)...
Epoch 1: Train Loss = 1.3641, Train Acc = 50.50%, Test Acc = 59.59%
Epoch 2: Train Loss = 0.8461, Train Acc = 70.17%, Test Acc = 72.50%
Epoch 3: Train Loss = 0.6437, Train Acc = 77.67%, Test Acc = 77.11%
Epoch 4: Train Loss = 0.5189, Train Acc = 81.94%, Test Acc = 77.62%
Epoch 5: Train Loss = 0.4177, Train Acc = 85.30%, Test Acc = 81.14%
Epoch 6: Train Loss = 0.3274, Train Acc = 88.45%, Test Acc = 80.30%
Epoch 7: Train Loss = 0.2447, Train Acc = 91.44%, Test Acc = 82.97%
Epoch 8: Train Loss = 0.1833, Train Acc = 93.43%, Test Acc = 81.09%
Epoch 9: Train Loss = 0.1268, Train Acc = 95.46%, Test Acc = 82.36%
Epoch 10: Train Loss = 0.0975, Train Acc = 96.58%, Test Acc = 81.38%
âœ… Training Complete!
